Workbook

Sheet Profit and Loss
B2: Demo Café Group
B3: Profit and loss (KSh '000)
B4: Account / breakdown | F4: 2024 | G4: 2025 | H4: Variance | I4: Variance % | J4: Remarks
B5: Revenue | F5: =ROUND(SUM('Profit and Loss'!F6,'Profit and Loss'!F7,'Profit and Loss'!F8),0) -> 4053112 | G5: =ROUND(SUM('Profit and Loss'!G6,'Profit and Loss'!G7,'Profit and Loss'!G8),0) -> 4345651 | H5: =G5-F5 -> 292539 | I5: =IF(F5=0,"",H5/ABS(F5)) -> 0.072176392 | J5: Revenue increased by KSh 292.539m (7.2%) compared with 2024. Beverage sales contributed KSh 208.683m of the KSh 292.539m growth, while food-related sales added KSh 78.671m. The wider outlet network and a strong December trading period supported the increase.
B6: Revenue from sale of food | F6: 2750555.5 | G6: 2829227 | H6: =G6-F6 -> 78671.489 | I6: =IF(F6=0,"",H6/ABS(F6)) -> 0.028602037 | J6: Revenue from sale of food increased by KSh 78.671m (2.9%) compared with 2024. The increase is consistent with a larger trading network, although growth was modest relative to total revenue. Food-related sales therefore contributed less to overall growth than beverages.
B7: Revenue from sale of beverages | F7: 1294302.5 | G7: 1502985.3 | H7: =G7-F7 -> 208682.8 | I7: =IF(F7=0,"",H7/ABS(F7)) -> 0.16123187 | J7: Revenue from sale of beverages increased by KSh 208.683m (16.1%) compared with 2024. This was the main revenue growth driver, contributing about 71% of the total increase. The movement is consistent with higher beverage volumes across the expanded restaurant network.
B8: Revenue from sale of other items | F8: 8253.751 | G8: 13438.51 | H8: =G8-F8 -> 5184.759 | I8: =IF(F8=0,"",H8/ABS(F8)) -> 0.62817003 | J8: Revenue from sale of other items increased by KSh 5.185m (62.8%) compared with 2024. The increase came from a small base and includes tobacco and other ancillary sales. Reclassification between food, beverage and other revenue categories may also affect the year-on-year comparison.
B10: Cost of sales | F10: =-ROUND('Schedule of Expenses'!F11,0) -> -2026099 | G10: =-ROUND('Schedule of Expenses'!G11,0) -> -2067896 | H10: =G10-F10 -> -41797 | I10: =IF(F10=0,"",H10/ABS(F10)) -> -0.020629298 | J10: Cost of sales increased by KSh 41.797m (2.1%) compared with 2024. Food costs and production salaries increased by KSh 35.941m and KSh 21.155m respectively. These increases were partly offset by lower utilities, packaging and kitchen-equipment depreciation.
B11: Food costs | F11: =-'Schedule of Expenses'!F6 -> -1460153.8 | G11: =-'Schedule of Expenses'!G6 -> -1496095.2 | H11: =G11-F11 -> -35941.318 | I11: =IF(F11=0,"",H11/ABS(F11)) -> -0.024614748 | J11: Food costs increased by KSh 35.941m (2.5%) compared with 2024. The movement reflects higher consumption as sales and the outlet network expanded. Costs grew more slowly than revenue, improving food-cost absorption during the year.
B12: Lighting, water and heating | F12: =-'Schedule of Expenses'!F7 -> -233482.13 | G12: =-'Schedule of Expenses'!G7 -> -226081.31 | H12: =G12-F12 -> 7400.82 | I12: =IF(F12=0,"",H12/ABS(F12)) -> 0.031697586 | J12: Lighting, water and heating decreased by KSh 7.401m (3.2%) compared with 2024. Utility costs reduced despite higher sales, indicating improved consumption or tariff management. The cost represented a lower proportion of revenue than in 2024.
B13: Depreciation - kitchen equipment | F13: =-'Schedule of Expenses'!F8 -> -45877.086 | G13: =-'Schedule of Expenses'!G8 -> -43082.723 | H13: =G13-F13 -> 2794.363 | I13: =IF(F13=0,"",H13/ABS(F13)) -> 0.060909775 | J13: Depreciation - kitchen equipment decreased by KSh 2.794m (6.1%) compared with 2024. The lower charge is consistent with disposals and the changing age profile of kitchen assets. Current-year additions partly offset the reduction in the depreciable base.
B14: Packaging materials | F14: =-'Schedule of Expenses'!F9 -> -83870.664 | G14: =-'Schedule of Expenses'!G9 -> -78766.514 | H14: =G14-F14 -> 5104.15 | I14: =IF(F14=0,"",H14/ABS(F14)) -> 0.060857393 | J14: Packaging materials decreased by KSh 5.104m (6.1%) compared with 2024. Packaging costs fell despite revenue growth, suggesting better purchasing, stock control or lower packaging intensity. This provided a favourable offset within cost of sales.
B15: Salaries | F15: =-'Schedule of Expenses'!F10 -> -202715.31 | G15: =-'Schedule of Expenses'!G10 -> -223870.54 | H15: =G15-F15 -> -21155.221 | I15: =IF(F15=0,"",H15/ABS(F15)) -> -0.10435926 | J15: Salaries increased by KSh 21.155m (10.4%) compared with 2024. Production payroll rose as the business operated a broader outlet network. The increase was above food-sales growth, indicating a higher staffing run rate during the year.
B16: Gross profit | F16: =SUM('Profit and Loss'!F5,'Profit and Loss'!F10) -> 2027013 | G16: =SUM('Profit and Loss'!G5,'Profit and Loss'!G10) -> 2277755 | H16: =G16-F16 -> 250742 | I16: =IF(F16=0,"",H16/ABS(F16)) -> 0.12370024 | J16: Gross profit increased by KSh 250.742m (12.4%) compared with 2024. Revenue grew by KSh 292.539m while cost of sales increased by only KSh 41.797m. As a result, gross margin improved from about 50.0% to 52.4%.
B18: Other operating income | F18: =SUM('Profit and Loss'!F19,'Profit and Loss'!F20) -> 4815.158 | G18: =SUM('Profit and Loss'!G19,'Profit and Loss'!G20) -> 1411.782 | H18: =G18-F18 -> -3403.376 | I18: =IF(F18=0,"",H18/ABS(F18)) -> -0.70680464 | J18: Other operating income decreased by KSh 3.403m (70.7%) compared with 2024. The reduction mainly reflects the non-recurrence of KSh 3.554m of other income reported in 2024. The increase in interest income was not sufficient to offset this fall.
B19: Interest income | F19: 1260.674 | G19: 1411.782 | H19: =G19-F19 -> 151.108 | I19: =IF(F19=0,"",H19/ABS(F19)) -> 0.11986287 | J19: Interest income increased by KSh 0.151m (12.0%) compared with 2024. The increase is consistent with higher returns on staff loans and foreign-currency project balances. The movement was modest in absolute terms and did not materially affect operating results.
B20: Other income | F20: 3554.484 | G20: 0 | H20: =G20-F20 -> -3554.484 | I20: =IF(F20=0,"",H20/ABS(F20)) -> -1 | J20: Other income was nil in 2025, compared with KSh 3.554m in 2024. The separate miscellaneous-income balance reported in 2024 did not recur in 2025. This appears to reflect a change in classification or the absence of the underlying one-off income.
B22: Sales and marketing expenses | F22: =-ROUND('Schedule of Expenses'!F16,0) -> -115182 | G22: =-ROUND('Schedule of Expenses'!G16,0) -> -154247 | H22: =G22-F22 -> -39065 | I22: =IF(F22=0,"",H22/ABS(F22)) -> -0.3391589 | J22: Sales and marketing expenses increased by KSh 39.065m (33.9%) compared with 2024. Advertising and delivery costs increased by KSh 26.196m and KSh 12.869m respectively. The higher spend is consistent with expanded marketing activity and growth in delivery-based sales.
B23: Advertising costs | F23: =-'Schedule of Expenses'!F14 -> -55650.826 | G23: =-'Schedule of Expenses'!G14 -> -81846.882 | H23: =G23-F23 -> -26196.056 | I23: =IF(F23=0,"",H23/ABS(F23)) -> -0.47072178 | J23: Advertising costs increased by KSh 26.196m (47.1%) compared with 2024. The increase reflects heavier campaign activity, including outlet launches, airport-location marketing, consultancy support and billboards. The scale of growth was well above revenue growth and should be supported by campaign documentation.
B24: Delivery costs | F24: =-'Schedule of Expenses'!F15 -> -59531.207 | G24: =-'Schedule of Expenses'!G15 -> -72400.102 | H24: =G24-F24 -> -12868.895 | I24: =IF(F24=0,"",H24/ABS(F24)) -> -0.21617057 | J24: Delivery costs increased by KSh 12.869m (21.6%) compared with 2024. The movement is consistent with higher delivery volumes and platform commissions. Delivery charges remained concentrated among the major delivery platforms.
B26: Administrative expenses | F26: =-ROUND('Schedule of Expenses'!F53,0) -> -1000264 | G26: =-ROUND('Schedule of Expenses'!G53,0) -> -1157300 | H26: =G26-F26 -> -157036 | I26: =IF(F26=0,"",H26/ABS(F26)) -> -0.15699455 | J26: Administrative expenses increased by KSh 157.036m (15.7%) compared with 2024. Employment costs increased by KSh 90.891m and other administration costs by KSh 66.145m. Payroll, professional services, travel and directors’ remuneration were the main drivers.
B27: Employment
B28: Salaries and wages | F28: =-'Schedule of Expenses'!F20 -> -745941 | G28: =-'Schedule of Expenses'!G20 -> -798708.54 | H28: =G28-F28 -> -52767.536 | I28: =IF(F28=0,"",H28/ABS(F28)) -> -0.070739557 | J28: Salaries and wages increased by KSh 52.768m (7.1%) compared with 2024. The increase was mainly driven by the KSh 46.022m rise in salaries excluding NSSF and KSh 6.745m in employer NSSF. This is consistent with a larger workforce and higher payroll run rate across the expanded network.
B29: Salaries excluding NSSF | F29: =-'Schedule of Expenses'!F21 -> -715425.5 | G29: =-'Schedule of Expenses'!G21 -> -761447.58 | H29: =G29-F29 -> -46022.081 | I29: =IF(F29=0,"",H29/ABS(F29)) -> -0.064328265 | J29: Salaries excluding NSSF increased by KSh 46.022m (6.4%) compared with 2024. The movement reflects the higher staffing requirement of the expanded outlet network. The year-end payroll run rate was above the level recorded at the start of the year.
B30: National Social Security Fund | F30: =-'Schedule of Expenses'!F22 -> -30515.502 | G30: =-'Schedule of Expenses'!G22 -> -37260.957 | H30: =G30-F30 -> -6745.455 | I30: =IF(F30=0,"",H30/ABS(F30)) -> -0.22105011 | J30: National Social Security Fund increased by KSh 6.745m (22.1%) compared with 2024. Employer contributions rose faster than base salaries, consistent with statutory contribution changes and a larger covered payroll. The contribution should be agreed to payroll and statutory returns.
B31: Staff welfare | F31: =-'Schedule of Expenses'!F23 -> -9231.594 | G31: =-'Schedule of Expenses'!G23 -> -9970.814 | H31: =G31-F31 -> -739.22 | I31: =IF(F31=0,"",H31/ABS(F31)) -> -0.080075012 | J31: Staff welfare increased by KSh 0.739m (8.0%) compared with 2024. The increase is consistent with higher welfare and training needs for a larger workforce. The movement remained modest relative to total employment costs.
B32: Staff uniform | F32: =-'Schedule of Expenses'!F24 -> -4975.708 | G32: =-'Schedule of Expenses'!G24 -> -5053.69 | H32: =G32-F32 -> -77.982 | I32: =IF(F32=0,"",H32/ABS(F32)) -> -0.015672543 | J32: Staff uniform increased by KSh 0.078m (1.6%) compared with 2024. Uniform expenditure was broadly stable despite the wider outlet network. This suggests purchases were controlled or uniforms issued in prior periods continued to be used.
B33: Staff transport | F33: =-'Schedule of Expenses'!F25 -> -42533.02 | G33: =-'Schedule of Expenses'!G25 -> -45581.238 | H33: =G33-F33 -> -3048.218 | I33: =IF(F33=0,"",H33/ABS(F33)) -> -0.071667095 | J33: Staff transport increased by KSh 3.048m (7.2%) compared with 2024. The increase is consistent with additional staff and locations requiring transport support. Growth was broadly in line with revenue.
B34: Work permit expenses | F34: =-'Schedule of Expenses'!F26 -> -940.016 | G34: =-'Schedule of Expenses'!G26 -> -4685.898 | H34: =G34-F34 -> -3745.882 | I34: =IF(F34=0,"",H34/ABS(F34)) -> -3.984913 | J34: Work permit expenses increased by KSh 3.746m (398.5%) compared with 2024. The sharp increase reflects several significant permit-related payments during the year. The movement is concentrated and should be supported by the relevant permits and payment records.
B35: Net change in provision for leave | F35: =-'Schedule of Expenses'!F27 -> 19101.286 | G35: =-'Schedule of Expenses'!G27 -> -480.034 | H35: =G35-F35 -> -19581.32 | I35: =IF(F35=0,"",H35/ABS(F35)) -> -1.025131 | J35: Net change in provision for leave moved from a credit of KSh 19.101m in 2024 to a charge of KSh 0.480m in 2025. The prior-year leave-provision reversal did not recur. A small charge was recognised in 2025, creating an adverse year-on-year movement of KSh 19.581m.
B36: Provision for gratuity | F36: =-'Schedule of Expenses'!F28 -> -4340.52 | G36: =-'Schedule of Expenses'!G28 -> -5249.309 | H36: =G36-F36 -> -908.789 | I36: =IF(F36=0,"",H36/ABS(F36)) -> -0.2093733 | J36: Provision for gratuity increased by KSh 0.909m (20.9%) compared with 2024. The higher charge is consistent with an increased employee-benefit obligation and service cost. The final expense should agree to the actuarial report and gratuity reconciliation.
B37: Gratuity interest cost | F37: =-'Schedule of Expenses'!F29 -> 0 | G37: =-'Schedule of Expenses'!G29 -> -10022.322 | H37: =G37-F37 -> -10022.322 | I37: =IF(F37=0,"",H37/ABS(F37)) | J37: Gratuity interest cost was recorded at KSh 10.022m in 2025, with no comparable amount in 2024. A separate interest cost on the gratuity obligation was recognised for the first time in 2025. This added KSh 10.022m to employment costs and should agree to the actuarial valuation.
B38: Total employment costs | F38: =-'Schedule of Expenses'!F30 -> -788860.57 | G38: =-'Schedule of Expenses'!G30 -> -879751.84 | H38: =G38-F38 -> -90891.269 | I38: =IF(F38=0,"",H38/ABS(F38)) -> -0.11521842 | J38: Total employment costs increased by KSh 90.891m (11.5%) compared with 2024. The main drivers were the KSh 52.768m rise in salaries and NSSF, the KSh 19.581m leave-provision swing and the new KSh 10.022m gratuity interest charge. Together, these explain most of the increase.
B39: Other administration expenses
B40: Directors remuneration | F40: =-'Schedule of Expenses'!F33 -> -47212.821 | G40: =-'Schedule of Expenses'!G33 -> -61535.099 | H40: =G40-F40 -> -14322.279 | I40: =IF(F40=0,"",H40/ABS(F40)) -> -0.30335571 | J40: Directors remuneration increased by KSh 14.322m (30.3%) compared with 2024. The increase forms part of the overall rise in compensation costs. The balance should be agreed to approved remuneration schedules and related-party disclosures.
B41: Directors expenses | F41: =-'Schedule of Expenses'!F34 -> -4080 | G41: =-'Schedule of Expenses'!G34 -> -7055.7 | H41: =G41-F41 -> -2975.7 | I41: =IF(F41=0,"",H41/ABS(F41)) -> -0.72933824 | J41: Directors expenses increased by KSh 2.976m (72.9%) compared with 2024. The movement includes a director-related prior-period PAYE item recorded in 2025. This makes the increase partly non-recurring rather than purely current-year operating spend.
B42: Legal and professional fees | F42: =-'Schedule of Expenses'!F35 -> -31278.778 | G42: =-'Schedule of Expenses'!G35 -> -56211.184 | H42: =G42-F42 -> -24932.406 | I42: =IF(F42=0,"",H42/ABS(F42)) -> -0.79710294 | J42: Legal and professional fees increased by KSh 24.932m (79.7%) compared with 2024. The increase is consistent with a full year of e-commerce project support, website and catalogue services, and guest-experience roles. The balance also includes tax-related professional charges.
B43: Auditors remuneration
B44: Current year | F44: =-'Schedule of Expenses'!F37 -> -3328.755 | G44: =-'Schedule of Expenses'!G37 -> -4105.914 | H44: =G44-F44 -> -777.159 | I44: =IF(F44=0,"",H44/ABS(F44)) -> -0.23346837 | J44: Current year increased by KSh 0.777m (23.3%) compared with 2024. The audit fee increased broadly in line with the revised engagement charge. The balance should agree to the signed engagement letter and supplier invoices.
B45: Postages, telephones and internet | F45: =-'Schedule of Expenses'!F38 -> -15203.122 | G45: =-'Schedule of Expenses'!G38 -> -15463.742 | H45: =G45-F45 -> -260.62 | I45: =IF(F45=0,"",H45/ABS(F45)) -> -0.017142532 | J45: Postages, telephones and internet increased by KSh 0.261m (1.7%) compared with 2024. The modest increase is consistent with servicing more operating locations. Internet costs remain the largest component of this line.
...

Sheet Balance Sheet
B2: Demo Café Group
B3: Balance sheet (KSh '000)
B4: Account / breakdown | F4: 2024 | G4: 2025 | H4: Variance | I4: Variance % | J4: Remarks
B5: CAPITAL EMPLOYED
B6: Share capital | F6: 1000 | G6: 1000 | H6: =G6-F6 -> 0 | I6: =IF(F6=0,"",H6/ABS(F6)) -> 0 | J6: Share capital decreased by KSh 0.000m (0.0%) compared with 2024. No new ordinary shares were issued during the year; the increase in funding was recorded through preference shares instead.
B7: Preference share capital - nominal | F7: 134566 | G7: 186192 | H7: =G7-F7 -> 51626 | I7: =IF(F7=0,"",H7/ABS(F7)) -> 0.38364817 | J7: Preference share capital - nominal increased by KSh 51.626m (38.4%) compared with 2024. New preference-share allotments increased nominal capital by KSh 51.626m. Together with the related premium, the issue added KSh 516.260m of funding.
B8: Preference share capital - premium | F8: 1211094 | G8: 1675728 | H8: =G8-F8 -> 464634 | I8: =IF(F8=0,"",H8/ABS(F8)) -> 0.38364817 | J8: Preference share capital - premium increased by KSh 464.634m (38.4%) compared with 2024. The increase is the premium component of the 2025 preference-share allotments. It should agree to allotment records, shareholder resolutions and cash receipts.
B9: Shareholders funds awaiting allotment | F9: 0.13 | G9: 5.603 | H9: =G9-F9 -> 5.473 | I9: =IF(F9=0,"",H9/ABS(F9)) -> 42.1 | J9: Shareholders funds awaiting allotment increased by KSh 0.005m (4,210.0%) compared with 2024. The closing balance is small and represents funding not yet allocated to share capital. It should be agreed to the share-allotment reconciliation.
B10: Accumulated deficit | F10: =SUM('Balance Sheet'!F11,'Profit and Loss'!F91,'Profit and Loss'!F95) -> -2891043.9 | G10: =SUM('Balance Sheet'!G11,'Profit and Loss'!G91,'Profit and Loss'!G95) -> -2949650.2 | H10: =G10-F10 -> -58606.3 | I10: =IF(F10=0,"",H10/ABS(F10)) -> -0.020271674 | J10: Accumulated deficit increased by KSh 58.606m (2.0%) compared with 2024. The deficit increased by the KSh 48.515m loss for the year and KSh 10.092m other comprehensive loss. These movements total the KSh 58.606m increase.
B11: Accumulated deficit at start of year | F11: -2772459.8 | G11: -2891043.9 | H11: =G11-F11 -> -118584.04 | I11: =IF(F11=0,"",H11/ABS(F11)) -> -0.042772141 | J11: Accumulated deficit at start of year increased by KSh 118.584m (4.3%) compared with 2024. The movement represents the prior-year total comprehensive loss carried into the 2025 opening balance. It should agree to the prior-year closing equity position.
B12: Loss for the year | F12: ='Profit and Loss'!F91 -> -117470.04 | G12: ='Profit and Loss'!G91 -> -48514.753 | H12: =G12-F12 -> 68955.291 | I12: =IF(F12=0,"",H12/ABS(F12)) -> 0.58700319 | J12: Loss for the year decreased by KSh 68.955m (58.7%) compared with 2024. The loss narrowed as operating profit improved, although finance costs remained significant. The amount agrees to the profit and loss statement.
B13: Other comprehensive loss | F13: ='Profit and Loss'!F95 -> -1114 | G13: ='Profit and Loss'!G95 -> -10091.547 | H13: =G13-F13 -> -8977.547 | I13: =IF(F13=0,"",H13/ABS(F13)) -> -8.0588393 | J13: Other comprehensive loss increased by KSh 8.978m (805.9%) compared with 2024. The increase reflects the larger actuarial remeasurement loss on staff gratuity. The amount should agree to the actuarial valuation.
B14: Shareholders deficit | F14: =SUM('Balance Sheet'!F6,'Balance Sheet'!F7,'Balance Sheet'!F8,'Balance Sheet'!F9,'Balance Sheet'!F10) -> -1544383.7 | G14: =SUM('Balance Sheet'!G6,'Balance Sheet'!G7,'Balance Sheet'!G8,'Balance Sheet'!G9,'Balance Sheet'!G10) -> -1086724.6 | H14: =G14-F14 -> 457659.17 | I14: =IF(F14=0,"",H14/ABS(F14)) -> 0.29633773 | J14: Shareholders deficit decreased by KSh 457.659m (29.6%) compared with 2024. Preference-share funding of KSh 516.260m more than offset the KSh 58.606m total comprehensive loss. This reduced the shareholders’ deficit by KSh 457.659m.
B16: Non-current liabilities
B17: Borrowings | F17: =SUM('Balance Sheet'!F18,'Balance Sheet'!F19) -> 385671.11 | G17: =SUM('Balance Sheet'!G18,'Balance Sheet'!G19) -> 286140.18 | H17: =G17-F17 -> -99530.923 | I17: =IF(F17=0,"",H17/ABS(F17)) -> -0.25807202 | J17: Borrowings decreased by KSh 99.531m (25.8%) compared with 2024. The reduction mainly reflects the fall in bank overdraft and non-current term-loan balances. Current term-loan instalments partly offset this decrease.
B18: Term loans | F18: 384458.08 | G18: 283040.72 | H18: =G18-F18 -> -101417.36 | I18: =IF(F18=0,"",H18/ABS(F18)) -> -0.26379302 | J18: Term loans decreased by KSh 101.417m (26.4%) compared with 2024. Scheduled repayments reduced the total loan exposure, while amounts due within twelve months were reclassified to current liabilities. The balance should agree to lender statements and amortisation schedules.
B19: Finance lease | F19: 1213.024 | G19: 3099.461 | H19: =G19-F19 -> 1886.437 | I19: =IF(F19=0,"",H19/ABS(F19)) -> 1.5551522 | J19: Finance lease increased by KSh 1.886m (155.5%) compared with 2024. The movement reflects changes in hire-purchase or finance-lease facilities and the split between current and non-current portions. It should agree to the underlying repayment schedules.
B20: Lease liabilities | F20: 898775.77 | G20: 1050523.7 | H20: =G20-F20 -> 151747.97 | I20: =IF(F20=0,"",H20/ABS(F20)) -> 0.16883852 | J20: Lease liabilities increased by KSh 151.748m (16.9%) compared with 2024. New leases increased the longer-term liability, while payments, concessions and modifications reduced the balance. The movement should agree to the IFRS 16 lease roll-forward.
B21: Total non-current liabilities | F21: =SUM('Balance Sheet'!F17,'Balance Sheet'!F20) -> 1284446.9 | G21: =SUM('Balance Sheet'!G17,'Balance Sheet'!G20) -> 1336663.9 | H21: =G21-F21 -> 52217.045 | I21: =IF(F21=0,"",H21/ABS(F21)) -> 0.040653331 | J21: Total non-current liabilities increased by KSh 52.217m (4.1%) compared with 2024. The KSh 151.748m increase in non-current lease liabilities exceeded the KSh 99.531m reduction in non-current borrowings. This produced a net KSh 52.217m increase.
B22: Total capital employed | F22: =SUM('Balance Sheet'!F14,'Balance Sheet'!F21) -> -259936.87 | G22: =SUM('Balance Sheet'!G14,'Balance Sheet'!G21) -> 249939.35 | H22: =G22-F22 -> 509876.22 | I22: =IF(F22=0,"",H22/ABS(F22)) -> 1.9615387 | J22: Total capital employed moved from a charge of KSh 259.937m in 2024 to a credit of KSh 249.939m in 2025. Additional preference-share funding and non-current liabilities moved the balance into a positive position. The change also incorporates the current-year comprehensive loss.
B24: REPRESENTED BY
B25: Non-current assets
B26: Property, plant and equipment | F26: 630019 | G26: 584861 | H26: =G26-F26 -> -45158 | I26: =IF(F26=0,"",H26/ABS(F26)) -> -0.071677203 | J26: Property, plant and equipment decreased by KSh 45.158m (7.2%) compared with 2024. Additions were outweighed by depreciation and disposals, reducing the net carrying amount. The balance should agree to the fixed-asset register.
B27: Leasehold improvements | F27: 278548 | G27: 226244 | H27: =G27-F27 -> -52304 | I27: =IF(F27=0,"",H27/ABS(F27)) -> -0.18777374 | J27: Leasehold improvements decreased by KSh 52.304m (18.8%) compared with 2024. Depreciation and disposals exceeded additions and transfers from work in progress. This reduced the closing carrying value materially.
B28: Buildings | F28: 0 | G28: 0 | H28: =G28-F28 -> 0 | I28: =IF(F28=0,"",H28/ABS(F28)) | J28: No balance was recorded for buildings in either year. The building asset had already been disposed of, with no additions or remaining carrying value in either year.
B29: Motor vehicles | F29: 4526 | G29: 5348 | H29: =G29-F29 -> 822 | I29: =IF(F29=0,"",H29/ABS(F29)) -> 0.18161732 | J29: Motor vehicles increased by KSh 0.822m (18.2%) compared with 2024. Current-year additions exceeded depreciation, producing a modest increase in carrying value. Disposals had little remaining net book value.
B30: Furniture, fittings and equipment | F30: 74759 | G30: 65624 | H30: =G30-F30 -> -9135 | I30: =IF(F30=0,"",H30/ABS(F30)) -> -0.12219265 | J30: Furniture, fittings and equipment decreased by KSh 9.135m (12.2%) compared with 2024. Depreciation and disposals exceeded additions and transfers from work in progress. The movement should agree to the asset register.
B31: Computer equipment | F31: 11871 | G31: 12780 | H31: =G31-F31 -> 909 | I31: =IF(F31=0,"",H31/ABS(F31)) -> 0.076573161 | J31: Computer equipment increased by KSh 0.909m (7.7%) compared with 2024. Additions exceeded depreciation, resulting in a modest net increase. The balance should be supported by invoices and the asset register.
B32: Kitchen equipment | F32: 85476 | G32: 81142 | H32: =G32-F32 -> -4334 | I32: =IF(F32=0,"",H32/ABS(F32)) -> -0.050704291 | J32: Kitchen equipment decreased by KSh 4.334m (5.1%) compared with 2024. Additions and transfers were insufficient to offset depreciation and disposals. The carrying amount therefore reduced despite investment during the year.
B33: Communications and office equipment | F33: 112885 | G33: 88888 | H33: =G33-F33 -> -23997 | I33: =IF(F33=0,"",H33/ABS(F33)) -> -0.21257917 | J33: Communications and office equipment decreased by KSh 23.997m (21.3%) compared with 2024. Depreciation exceeded additions, and disposals further reduced the balance. This indicates an ageing asset base despite current-year purchases.
B34: Cutlery | F34: 25626 | G34: 27160 | H34: =G34-F34 -> 1534 | I34: =IF(F34=0,"",H34/ABS(F34)) -> 0.059861079 | J34: Cutlery increased by KSh 1.534m (6.0%) compared with 2024. Additions and transfers slightly exceeded depreciation and disposals. The balance remained broadly stable relative to the expanded network.
B35: Capital work in progress | F35: 36328 | G35: 77675 | H35: =G35-F35 -> 41347 | I35: =IF(F35=0,"",H35/ABS(F35)) -> 1.1381579 | J35: Capital work in progress increased by KSh 41.347m (113.8%) compared with 2024. The increase reflects capital purchases not yet available for use at year end. Transfers to operating asset classes partly offset additions.
B36: Right-of-use assets | F36: =SUM('Balance Sheet'!F37,'Balance Sheet'!F38) -> 923547.25 | G36: =SUM('Balance Sheet'!G37,'Balance Sheet'!G38) -> 1157167.7 | H36: =G36-F36 -> 233620.45 | I36: =IF(F36=0,"",H36/ABS(F36)) -> 0.25295993 | J36: Right-of-use assets increased by KSh 233.620m (25.3%) compared with 2024. New leases and modifications increased gross cost, while depreciation reduced the net balance. The movement should agree to the lease roll-forward.
B37: Cost at year end | F37: 2597976.6 | G37: 3129223.8 | H37: =G37-F37 -> 531247.25 | I37: =IF(F37=0,"",H37/ABS(F37)) -> 0.20448501 | J37: Cost at year end increased by KSh 531.247m (20.4%) compared with 2024. The increase reflects additions during the year and should agree to the relevant fixed-asset or lease roll-forward.
B38: Less: accumulated depreciation | F38: -1674429.3 | G38: -1972056.1 | H38: =G38-F38 -> -297626.81 | I38: =IF(F38=0,"",H38/ABS(F38)) -> -0.17774821 | J38: Less: accumulated depreciation increased by KSh 297.627m (17.8%) compared with 2024. The higher accumulated charge reflects the current-year depreciation or amortisation expense, net of amounts removed on disposals.
B39: Intangible assets - computer software | F39: =SUM('Balance Sheet'!F40,'Balance Sheet'!F41) -> 1735.287 | G39: =SUM('Balance Sheet'!G40,'Balance Sheet'!G41) -> 15504.74 | H39: =G39-F39 -> 13769.453 | I39: =IF(F39=0,"",H39/ABS(F39)) -> 7.9349716 | J39: Intangible assets - computer software increased by KSh 13.769m (793.5%) compared with 2024. Software additions materially increased the asset base, with amortisation only partly offsetting the growth. The balance should agree to the intangible-asset register.
B40: Cost at year end | F40: 29101.206 | G40: 47169.409 | H40: =G40-F40 -> 18068.203 | I40: =IF(F40=0,"",H40/ABS(F40)) -> 0.62087472 | J40: Cost at year end increased by KSh 18.068m (62.1%) compared with 2024. The increase reflects additions during the year and should agree to the relevant fixed-asset or lease roll-forward.
B41: Less: accumulated amortisation | F41: -27365.919 | G41: -31664.669 | H41: =G41-F41 -> -4298.75 | I41: =IF(F41=0,"",H41/ABS(F41)) -> -0.15708407 | J41: Less: accumulated amortisation increased by KSh 4.299m (15.7%) compared with 2024. The higher accumulated charge reflects the current-year depreciation or amortisation expense, net of amounts removed on disposals.
B42: Intangible assets - acquired trademarks | F42: =SUM('Balance Sheet'!F43,'Balance Sheet'!F44) -> 0 | G42: =SUM('Balance Sheet'!G43,'Balance Sheet'!G44) -> 0 | H42: =G42-F42 -> 0 | I42: =IF(F42=0,"",H42/ABS(F42)) | J42: No balance was recorded for intangible assets - acquired trademarks in either year. The trademarks were fully impaired in the prior year and had no remaining carrying value in 2025.
B43: Carrying amount at start of year | F43: 18500 | G43: 0 | H43: =G43-F43 -> -18500 | I43: =IF(F43=0,"",H43/ABS(F43)) -> -1 | J43: Carrying amount at start of year was nil in 2025, compared with KSh 18.500m in 2024. The prior-year carrying amount was fully impaired, leaving no opening balance for 2025.
...

Sheet Schedule of Expenses
B2: Demo Café Group
B3: Schedule of expenses (KSh '000)
B4: Account / breakdown | F4: 2024 | G4: 2025 | H4: Variance | I4: Variance % | J4: Remarks
B5: 1. COST OF SALES
B6: Food costs | F6: 1460153.8 | G6: 1496095.2 | H6: =G6-F6 -> 35941.318 | I6: =IF(F6=0,"",H6/ABS(F6)) -> 0.024614748 | J6: Food costs increased by KSh 35.941m (2.5%) compared with 2024. The movement reflects higher consumption as sales and the outlet network expanded. Costs grew more slowly than revenue, improving food-cost absorption during the year.
B7: Lighting, water and heating | F7: 233482.13 | G7: 226081.31 | H7: =G7-F7 -> -7400.82 | I7: =IF(F7=0,"",H7/ABS(F7)) -> -0.031697586 | J7: Lighting, water and heating decreased by KSh 7.401m (3.2%) compared with 2024. Utility costs reduced despite higher sales, indicating improved consumption or tariff management. The cost represented a lower proportion of revenue than in 2024.
B8: Depreciation - kitchen equipment | F8: 45877.086 | G8: 43082.723 | H8: =G8-F8 -> -2794.363 | I8: =IF(F8=0,"",H8/ABS(F8)) -> -0.060909775 | J8: Depreciation - kitchen equipment decreased by KSh 2.794m (6.1%) compared with 2024. The lower charge is consistent with disposals and the changing age profile of kitchen assets. Current-year additions partly offset the reduction in the depreciable base.
B9: Packaging materials | F9: 83870.664 | G9: 78766.514 | H9: =G9-F9 -> -5104.15 | I9: =IF(F9=0,"",H9/ABS(F9)) -> -0.060857393 | J9: Packaging materials decreased by KSh 5.104m (6.1%) compared with 2024. Packaging costs fell despite revenue growth, suggesting better purchasing, stock control or lower packaging intensity. This provided a favourable offset within cost of sales.
B10: Salaries | F10: 202715.31 | G10: 223870.54 | H10: =G10-F10 -> 21155.221 | I10: =IF(F10=0,"",H10/ABS(F10)) -> 0.10435926 | J10: Salaries increased by KSh 21.155m (10.4%) compared with 2024. Production payroll rose as the business operated a broader outlet network. The increase was above food-sales growth, indicating a higher staffing run rate during the year.
B11: Total cost of sales | F11: =SUM('Schedule of Expenses'!F6,'Schedule of Expenses'!F7,'Schedule of Expenses'!F8,'Schedule of Expenses'!F9,'Schedule of Expenses'!F10) -> 2026099 | G11: =SUM('Schedule of Expenses'!G6,'Schedule of Expenses'!G7,'Schedule of Expenses'!G8,'Schedule of Expenses'!G9,'Schedule of Expenses'!G10) -> 2067896.2 | H11: =G11-F11 -> 41797.206 | I11: =IF(F11=0,"",H11/ABS(F11)) -> 0.020629399 | J11: Total cost of sales increased by KSh 41.797m (2.1%) compared with 2024. Food costs and production salaries increased by KSh 35.941m and KSh 21.155m respectively. Lower utilities, packaging and kitchen depreciation partly offset the increase.
B13: 2. SALES AND MARKETING EXPENSES
B14: Advertising costs | F14: 55650.826 | G14: 81846.882 | H14: =G14-F14 -> 26196.056 | I14: =IF(F14=0,"",H14/ABS(F14)) -> 0.47072178 | J14: Advertising costs increased by KSh 26.196m (47.1%) compared with 2024. The increase reflects heavier campaign activity, including outlet launches, airport-location marketing, consultancy support and billboards. The scale of growth was well above revenue growth and should be supported by campaign documentation.
B15: Delivery costs | F15: 59531.207 | G15: 72400.102 | H15: =G15-F15 -> 12868.895 | I15: =IF(F15=0,"",H15/ABS(F15)) -> 0.21617057 | J15: Delivery costs increased by KSh 12.869m (21.6%) compared with 2024. The movement is consistent with higher delivery volumes and platform commissions. Delivery charges remained concentrated among the major delivery platforms.
B16: Total sales and marketing expenses | F16: =SUM('Schedule of Expenses'!F14,'Schedule of Expenses'!F15) -> 115182.03 | G16: =SUM('Schedule of Expenses'!G14,'Schedule of Expenses'!G15) -> 154246.98 | H16: =G16-F16 -> 39064.951 | I16: =IF(F16=0,"",H16/ABS(F16)) -> 0.33915837 | J16: Total sales and marketing expenses increased by KSh 39.065m (33.9%) compared with 2024. Advertising and delivery costs increased by KSh 26.196m and KSh 12.869m respectively. The higher spend is consistent with expanded marketing activity and delivery volumes.
B18: 3. ADMINISTRATIVE EXPENSES
B19: Employment
B20: Salaries and wages | F20: =SUM('Schedule of Expenses'!F21,'Schedule of Expenses'!F22) -> 745941 | G20: =SUM('Schedule of Expenses'!G21,'Schedule of Expenses'!G22) -> 798708.54 | H20: =G20-F20 -> 52767.536 | I20: =IF(F20=0,"",H20/ABS(F20)) -> 0.070739557 | J20: Salaries and wages increased by KSh 52.768m (7.1%) compared with 2024. The increase was mainly driven by the KSh 46.022m rise in salaries excluding NSSF and KSh 6.745m in employer NSSF. This is consistent with a larger workforce and higher payroll run rate across the expanded network.
B21: Salaries excluding NSSF | F21: 715425.5 | G21: 761447.58 | H21: =G21-F21 -> 46022.081 | I21: =IF(F21=0,"",H21/ABS(F21)) -> 0.064328265 | J21: Salaries excluding NSSF increased by KSh 46.022m (6.4%) compared with 2024. The movement reflects the higher staffing requirement of the expanded outlet network. The year-end payroll run rate was above the level recorded at the start of the year.
B22: National Social Security Fund | F22: 30515.502 | G22: 37260.957 | H22: =G22-F22 -> 6745.455 | I22: =IF(F22=0,"",H22/ABS(F22)) -> 0.22105011 | J22: National Social Security Fund increased by KSh 6.745m (22.1%) compared with 2024. Employer contributions rose faster than base salaries, consistent with statutory contribution changes and a larger covered payroll. The contribution should be agreed to payroll and statutory returns.
B23: Staff welfare | F23: 9231.594 | G23: 9970.814 | H23: =G23-F23 -> 739.22 | I23: =IF(F23=0,"",H23/ABS(F23)) -> 0.080075012 | J23: Staff welfare increased by KSh 0.739m (8.0%) compared with 2024. The increase is consistent with higher welfare and training needs for a larger workforce. The movement remained modest relative to total employment costs.
B24: Staff uniform | F24: 4975.708 | G24: 5053.69 | H24: =G24-F24 -> 77.982 | I24: =IF(F24=0,"",H24/ABS(F24)) -> 0.015672543 | J24: Staff uniform increased by KSh 0.078m (1.6%) compared with 2024. Uniform expenditure was broadly stable despite the wider outlet network. This suggests purchases were controlled or uniforms issued in prior periods continued to be used.
B25: Staff transport | F25: 42533.02 | G25: 45581.238 | H25: =G25-F25 -> 3048.218 | I25: =IF(F25=0,"",H25/ABS(F25)) -> 0.071667095 | J25: Staff transport increased by KSh 3.048m (7.2%) compared with 2024. The increase is consistent with additional staff and locations requiring transport support. Growth was broadly in line with revenue.
B26: Work permit expenses | F26: 940.016 | G26: 4685.898 | H26: =G26-F26 -> 3745.882 | I26: =IF(F26=0,"",H26/ABS(F26)) -> 3.984913 | J26: Work permit expenses increased by KSh 3.746m (398.5%) compared with 2024. The sharp increase reflects several significant permit-related payments during the year. The movement is concentrated and should be supported by the relevant permits and payment records.
B27: Net change in provision for leave | F27: -19101.286 | G27: 480.034 | H27: =G27-F27 -> 19581.32 | I27: =IF(F27=0,"",H27/ABS(F27)) -> 1.025131 | J27: Net change in provision for leave moved from a charge of KSh 19.101m in 2024 to a credit of KSh 0.480m in 2025. The prior-year leave-provision reversal did not recur. A small charge was recognised in 2025, creating an adverse year-on-year movement of KSh 19.581m.
B28: Provision for gratuity | F28: 4340.52 | G28: 5249.309 | H28: =G28-F28 -> 908.789 | I28: =IF(F28=0,"",H28/ABS(F28)) -> 0.2093733 | J28: Provision for gratuity increased by KSh 0.909m (20.9%) compared with 2024. The higher charge is consistent with an increased employee-benefit obligation and service cost. The final expense should agree to the actuarial report and gratuity reconciliation.
B29: Gratuity interest cost | F29: 0 | G29: 10022.322 | H29: =G29-F29 -> 10022.322 | I29: =IF(F29=0,"",H29/ABS(F29)) | J29: Gratuity interest cost was recorded at KSh 10.022m in 2025, with no comparable amount in 2024. A separate interest cost on the gratuity obligation was recognised for the first time in 2025. This added KSh 10.022m to employment costs and should agree to the actuarial valuation.
B30: Total employment costs | F30: =SUM('Schedule of Expenses'!F20,'Schedule of Expenses'!F23,'Schedule of Expenses'!F24,'Schedule of Expenses'!F25,'Schedule of Expenses'!F26,'Schedule of Expenses'!F27,'Schedule of Expenses'!F28,'Schedule of Expenses'!F29) -> 788860.57 | G30: =SUM('Schedule of Expenses'!G20,'Schedule of Expenses'!G23,'Schedule of Expenses'!G24,'Schedule of Expenses'!G25,'Schedule of Expenses'!G26,'Schedule of Expenses'!G27,'Schedule of Expenses'!G28,'Schedule of Expenses'!G29) -> 879751.84 | H30: =G30-F30 -> 90891.269 | I30: =IF(F30=0,"",H30/ABS(F30)) -> 0.11521842 | J30: Total employment costs increased by KSh 90.891m (11.5%) compared with 2024. The main drivers were the KSh 52.768m rise in salaries and NSSF, the KSh 19.581m leave-provision swing and the new KSh 10.022m gratuity interest charge. Together, these explain most of the increase.
B32: Other administration expenses
B33: Directors remuneration | F33: 47212.821 | G33: 61535.099 | H33: =G33-F33 -> 14322.279 | I33: =IF(F33=0,"",H33/ABS(F33)) -> 0.30335571 | J33: Directors remuneration increased by KSh 14.322m (30.3%) compared with 2024. The increase forms part of the overall rise in compensation costs. The balance should be agreed to approved remuneration schedules and related-party disclosures.
B34: Directors expenses | F34: 4080 | G34: 7055.7 | H34: =G34-F34 -> 2975.7 | I34: =IF(F34=0,"",H34/ABS(F34)) -> 0.72933824 | J34: Directors expenses increased by KSh 2.976m (72.9%) compared with 2024. The movement includes a director-related prior-period PAYE item recorded in 2025. This makes the increase partly non-recurring rather than purely current-year operating spend.
B35: Legal and professional fees | F35: 31278.778 | G35: 56211.184 | H35: =G35-F35 -> 24932.406 | I35: =IF(F35=0,"",H35/ABS(F35)) -> 0.79710294 | J35: Legal and professional fees increased by KSh 24.932m (79.7%) compared with 2024. The increase is consistent with a full year of e-commerce project support, website and catalogue services, and guest-experience roles. The balance also includes tax-related professional charges.
B36: Auditors remuneration
B37: Current year | F37: 3328.755 | G37: 4105.914 | H37: =G37-F37 -> 777.159 | I37: =IF(F37=0,"",H37/ABS(F37)) -> 0.23346837 | J37: Current year increased by KSh 0.777m (23.3%) compared with 2024. The audit fee increased broadly in line with the revised engagement charge. The balance should agree to the signed engagement letter and supplier invoices.
B38: Postages, telephones and internet | F38: 15203.122 | G38: 15463.742 | H38: =G38-F38 -> 260.62 | I38: =IF(F38=0,"",H38/ABS(F38)) -> 0.017142532 | J38: Postages, telephones and internet increased by KSh 0.261m (1.7%) compared with 2024. The modest increase is consistent with servicing more operating locations. Internet costs remain the largest component of this line.
B39: Printing and stationery | F39: 17635.862 | G39: 16174.117 | H39: =G39-F39 -> -1461.745 | I39: =IF(F39=0,"",H39/ABS(F39)) -> -0.082884806 | J39: Printing and stationery decreased by KSh 1.462m (8.3%) compared with 2024. The decrease is consistent with improved stock control and purchasing terms. The saving was achieved despite the larger operating network.
B40: Café decoration | F40: 1375.349 | G40: 5004.4 | H40: =G40-F40 -> 3629.051 | I40: =IF(F40=0,"",H40/ABS(F40)) -> 2.6386401 | J40: Café decoration increased by KSh 3.629m (263.9%) compared with 2024. The increase is consistent with decorating newly opened or refurbished outlets. The balance may also include timing effects from accruals and reversals around project completion.
B41: Motor vehicle running expenses | F41: 22056.853 | G41: 19606.944 | H41: =G41-F41 -> -2449.909 | I41: =IF(F41=0,"",H41/ABS(F41)) -> -0.11107246 | J41: Motor vehicle running expenses decreased by KSh 2.450m (11.1%) compared with 2024. The reduction is consistent with lower use of company vehicles after more logistics activity was outsourced. This saving was partly offset by higher travel and transport costs.
B42: Travelling and transport | F42: 30178.226 | G42: 46434.916 | H42: =G42-F42 -> 16256.69 | I42: =IF(F42=0,"",H42/ABS(F42)) -> 0.53868938 | J42: Travelling and transport increased by KSh 16.257m (53.9%) compared with 2024. The increase reflects the broader outlet network and greater use of outsourced logistics. Logistics-related charges appear to be the main component of the movement.
B43: Entertainment expenses | F43: -737.971 | G43: 0 | H43: =G43-F43 -> 737.971 | I43: =IF(F43=0,"",H43/ABS(F43)) -> 1 | J43: Entertainment expenses was nil in 2025, compared with KSh 0.738m in 2024. The prior-year balance did not recur, indicating that 2025 activities were either supplier-supported or offset by recoveries. The nil balance should be checked against the underlying gross entries.
B44: Bad debts / recoveries | F44: 11.941 | G44: 34.481 | H44: =G44-F44 -> 22.54 | I44: =IF(F44=0,"",H44/ABS(F44)) -> 1.8876141 | J44: Bad debts / recoveries increased by KSh 0.023m (188.8%) compared with 2024. More receivable balances were written off in 2025, although the amount remains immaterial. The write-offs should be matched to approved customer account closures.
...

Sheet Branch Sales
C2: Demo Café Group
C3: Branch sales (KSh)
B6: Rank | C6: Branch | D6: January sales | E6: January % | F6: February sales | G6: February % | H6: March sales | I6: March % | J6: April sales | K6: April % | L6: May sales | M6: May % | N6: June sales | O6: June % | P6: July sales | Q6: July % | R6: August sales | S6: August % | T6: September sales | U6: September % | V6: October sales | W6: October % | X6: November sales | Y6: November % | Z6: December sales | AA6: December % | AB6: Total sales 2025 | AC6: % of annual sales
B7: =COUNTIFS($AB$7:$AB$75,">"&AB7)+1 -> 1 | C7: Branch 1 | D7: 14677352 | E7: =IF(D$83=0,"n.a.",D7/D$83) -> 0.042080448 | F7: 15642673 | G7: =IF(F$83=0,"n.a.",F7/F$83) -> 0.047550892 | H7: 15913418 | I7: =IF(H$83=0,"n.a.",H7/H$83) -> 0.047189524 | J7: 14525120 | K7: =IF(J$83=0,"n.a.",J7/J$83) -> 0.042459502 | L7: 16743537 | M7: =IF(L$83=0,"n.a.",L7/L$83) -> 0.047824834 | N7: 15469226 | O7: =IF(N$83=0,"n.a.",N7/N$83) -> 0.044461291 | P7: 14969772 | Q7: =IF(P$83=0,"n.a.",P7/P$83) -> 0.040412416 | R7: 15330888 | S7: =IF(R$83=0,"n.a.",R7/R$83) -> 0.04038593 | T7: 15250802 | U7: =IF(T$83=0,"n.a.",T7/T$83) -> 0.04207252 | V7: 16749196 | W7: =IF(V$83=0,"n.a.",V7/V$83) -> 0.044637058 | X7: 18034117 | Y7: =IF(X$83=0,"n.a.",X7/X$83) -> 0.048933274 | Z7: 20304771 | AA7: =IF(Z$83=0,"n.a.",Z7/Z$83) -> 0.046758453 | AB7: =SUM(D7,F7,H7,J7,L7,N7,P7,R7,T7,V7,X7,Z7) -> 1.9361087e+08 | AC7: =IF($AB$83=0,"n.a.",AB7/$AB$83) -> 0.044552791
B8: =COUNTIFS($AB$7:$AB$75,">"&AB8)+1 -> 2 | C8: Branch 2 | D8: 16117266 | E8: =IF(D$83=0,"n.a.",D8/D$83) -> 0.046208731 | F8: 14476606 | G8: =IF(F$83=0,"n.a.",F8/F$83) -> 0.044006259 | H8: 13117884 | I8: =IF(H$83=0,"n.a.",H8/H$83) -> 0.038899669 | J8: 14869920 | K8: =IF(J$83=0,"n.a.",J8/J$83) -> 0.043467414 | L8: 14757867 | M8: =IF(L$83=0,"n.a.",L8/L$83) -> 0.042153133 | N8: 14603871 | O8: =IF(N$83=0,"n.a.",N8/N$83) -> 0.041974108 | P8: 14908990 | Q8: =IF(P$83=0,"n.a.",P8/P$83) -> 0.04024833 | R8: 15288034 | S8: =IF(R$83=0,"n.a.",R8/R$83) -> 0.04027304 | T8: 14562154 | U8: =IF(T$83=0,"n.a.",T8/T$83) -> 0.040172741 | V8: 14546451 | W8: =IF(V$83=0,"n.a.",V8/V$83) -> 0.038766685 | X8: 14210296 | Y8: =IF(X$83=0,"n.a.",X8/X$83) -> 0.038557823 | Z8: 16513974 | AA8: =IF(Z$83=0,"n.a.",Z8/Z$83) -> 0.038028888 | AB8: =SUM(D8,F8,H8,J8,L8,N8,P8,R8,T8,V8,X8,Z8) -> 1.7797331e+08 | AC8: =IF($AB$83=0,"n.a.",AB8/$AB$83) -> 0.040954353
B9: =COUNTIFS($AB$7:$AB$75,">"&AB9)+1 -> 3 | C9: Branch 3 | D9: 14107338 | E9: =IF(D$83=0,"n.a.",D9/D$83) -> 0.040446202 | F9: 13614205 | G9: =IF(F$83=0,"n.a.",F9/F$83) -> 0.041384716 | H9: 15110608 | I9: =IF(H$83=0,"n.a.",H9/H$83) -> 0.04480888 | J9: 13651635 | K9: =IF(J$83=0,"n.a.",J9/J$83) -> 0.039906152 | L9: 14711147 | M9: =IF(L$83=0,"n.a.",L9/L$83) -> 0.042019687 | N9: 13755073 | O9: =IF(N$83=0,"n.a.",N9/N$83) -> 0.039534514 | P9: 14000426 | Q9: =IF(P$83=0,"n.a.",P9/P$83) -> 0.037795569 | R9: 13991403 | S9: =IF(R$83=0,"n.a.",R9/R$83) -> 0.036857345 | T9: 13739566 | U9: =IF(T$83=0,"n.a.",T9/T$83) -> 0.037903459 | V9: 14183290 | W9: =IF(V$83=0,"n.a.",V9/V$83) -> 0.037798849 | X9: 13823648 | Y9: =IF(X$83=0,"n.a.",X9/X$83) -> 0.037508703 | Z9: 14480186 | AA9: =IF(Z$83=0,"n.a.",Z9/Z$83) -> 0.033345419 | AB9: =SUM(D9,F9,H9,J9,L9,N9,P9,R9,T9,V9,X9,Z9) -> 1.6916853e+08 | AC9: =IF($AB$83=0,"n.a.",AB9/$AB$83) -> 0.038928238
B10: =COUNTIFS($AB$7:$AB$75,">"&AB10)+1 -> 4 | C10: Branch 4 | D10: 12314010 | E10: =IF(D$83=0,"n.a.",D10/D$83) -> 0.03530467 | F10: 12617769 | G10: =IF(F$83=0,"n.a.",F10/F$83) -> 0.038355731 | H10: 12991422 | I10: =IF(H$83=0,"n.a.",H10/H$83) -> 0.038524661 | J10: 12918517 | K10: =IF(J$83=0,"n.a.",J10/J$83) -> 0.037763118 | L10: 13534177 | M10: =IF(L$83=0,"n.a.",L10/L$83) -> 0.038657888 | N10: 13427561 | O10: =IF(N$83=0,"n.a.",N10/N$83) -> 0.038593185 | P10: 14127378 | Q10: =IF(P$83=0,"n.a.",P10/P$83) -> 0.03813829 | R10: 13459133 | S10: =IF(R$83=0,"n.a.",R10/R$83) -> 0.035455192 | T10: 13346415 | U10: =IF(T$83=0,"n.a.",T10/T$83) -> 0.036818871 | V10: 13787246 | W10: =IF(V$83=0,"n.a.",V10/V$83) -> 0.036743383 | X10: 13358618 | Y10: =IF(X$83=0,"n.a.",X10/X$83) -> 0.036246905 | Z10: 13508492 | AA10: =IF(Z$83=0,"n.a.",Z10/Z$83) -> 0.031107773 | AB10: =SUM(D10,F10,H10,J10,L10,N10,P10,R10,T10,V10,X10,Z10) -> 1.5939074e+08 | AC10: =IF($AB$83=0,"n.a.",AB10/$AB$83) -> 0.036678221
B11: =COUNTIFS($AB$7:$AB$75,">"&AB11)+1 -> 5 | C11: Branch 5 | D11: 10189243 | E11: =IF(D$83=0,"n.a.",D11/D$83) -> 0.029212894 | F11: 10957795 | G11: =IF(F$83=0,"n.a.",F11/F$83) -> 0.033309711 | H11: 11216205 | I11: =IF(H$83=0,"n.a.",H11/H$83) -> 0.033260445 | J11: 10850937 | K11: =IF(J$83=0,"n.a.",J11/J$83) -> 0.031719214 | L11: 11008657 | M11: =IF(L$83=0,"n.a.",L11/L$83) -> 0.031444206 | N11: 11912310 | O11: =IF(N$83=0,"n.a.",N11/N$83) -> 0.034238087 | P11: 12662523 | Q11: =IF(P$83=0,"n.a.",P11/P$83) -> 0.034183765 | R11: 12635665 | S11: =IF(R$83=0,"n.a.",R11/R$83) -> 0.033285944 | T11: 11726791 | U11: =IF(T$83=0,"n.a.",T11/T$83) -> 0.032350799 | V11: 12169924 | W11: =IF(V$83=0,"n.a.",V11/V$83) -> 0.032433175 | X11: 11586426 | Y11: =IF(X$83=0,"n.a.",X11/X$83) -> 0.031438287 | Z11: 13838734 | AA11: =IF(Z$83=0,"n.a.",Z11/Z$83) -> 0.031868263 | AB11: =SUM(D11,F11,H11,J11,L11,N11,P11,R11,T11,V11,X11,Z11) -> 1.4075521e+08 | AC11: =IF($AB$83=0,"n.a.",AB11/$AB$83) -> 0.032389904
B12: =COUNTIFS($AB$7:$AB$75,">"&AB12)+1 -> 6 | C12: Branch 6 | D12: 12153972 | E12: =IF(D$83=0,"n.a.",D12/D$83) -> 0.034845837 | F12: 10389376 | G12: =IF(F$83=0,"n.a.",F12/F$83) -> 0.03158182 | H12: 10506386 | I12: =IF(H$83=0,"n.a.",H12/H$83) -> 0.031155553 | J12: 11062156 | K12: =IF(J$83=0,"n.a.",J12/J$83) -> 0.032336645 | L12: 11344419 | M12: =IF(L$83=0,"n.a.",L12/L$83) -> 0.032403247 | N12: 10994385 | O12: =IF(N$83=0,"n.a.",N12/N$83) -> 0.031599809 | P12: 11536859 | Q12: =IF(P$83=0,"n.a.",P12/P$83) -> 0.031144921 | R12: 11951632 | S12: =IF(R$83=0,"n.a.",R12/R$83) -> 0.031484006 | T12: 10683754 | U12: =IF(T$83=0,"n.a.",T12/T$83) -> 0.029473363 | V12: 10884967 | W12: =IF(V$83=0,"n.a.",V12/V$83) -> 0.02900873 | X12: 11289457 | Y12: =IF(X$83=0,"n.a.",X12/X$83) -> 0.030632498 | Z12: 13541641 | AA12: =IF(Z$83=0,"n.a.",Z12/Z$83) -> 0.031184108 | AB12: =SUM(D12,F12,H12,J12,L12,N12,P12,R12,T12,V12,X12,Z12) -> 1.36339e+08 | AC12: =IF($AB$83=0,"n.a.",AB12/$AB$83) -> 0.031373668
B13: =COUNTIFS($AB$7:$AB$75,">"&AB13)+1 -> 7 | C13: Branch 7 | D13: 10672572 | E13: =IF(D$83=0,"n.a.",D13/D$83) -> 0.030598613 | F13: 9881591.5 | G13: =IF(F$83=0,"n.a.",F13/F$83) -> 0.030038247 | H13: 10403047 | I13: =IF(H$83=0,"n.a.",H13/H$83) -> 0.030849113 | J13: 10223369 | K13: =IF(J$83=0,"n.a.",J13/J$83) -> 0.02988472 | L13: 10026711 | M13: =IF(L$83=0,"n.a.",L13/L$83) -> 0.028639456 | N13: 9925307.7 | O13: =IF(N$83=0,"n.a.",N13/N$83) -> 0.02852709 | P13: 11011253 | Q13: =IF(P$83=0,"n.a.",P13/P$83) -> 0.029725995 | R13: 11465858 | S13: =IF(R$83=0,"n.a.",R13/R$83) -> 0.030204339 | T13: 10244080 | U13: =IF(T$83=0,"n.a.",T13/T$83) -> 0.028260431 | V13: 11024568 | W13: =IF(V$83=0,"n.a.",V13/V$83) -> 0.029380771 | X13: 11104801 | Y13: =IF(X$83=0,"n.a.",X13/X$83) -> 0.03013146 | Z13: 13760346 | AA13: =IF(Z$83=0,"n.a.",Z13/Z$83) -> 0.03168775 | AB13: =SUM(D13,F13,H13,J13,L13,N13,P13,R13,T13,V13,X13,Z13) -> 1.297435e+08 | AC13: =IF($AB$83=0,"n.a.",AB13/$AB$83) -> 0.029855944
B14: =COUNTIFS($AB$7:$AB$75,">"&AB14)+1 -> 8 | C14: Branch 8 | D14: 9486653.5 | E14: =IF(D$83=0,"n.a.",D14/D$83) -> 0.027198547 | F14: 8509185.6 | G14: =IF(F$83=0,"n.a.",F14/F$83) -> 0.025866382 | H14: 9443319.9 | I14: =IF(H$83=0,"n.a.",H14/H$83) -> 0.028003147 | J14: 9873089.1 | K14: =IF(J$83=0,"n.a.",J14/J$83) -> 0.028860791 | L14: 10015162 | M14: =IF(L$83=0,"n.a.",L14/L$83) -> 0.028606468 | N14: 10813549 | O14: =IF(N$83=0,"n.a.",N14/N$83) -> 0.031080052 | P14: 10673975 | Q14: =IF(P$83=0,"n.a.",P14/P$83) -> 0.028815479 | R14: 11634947 | S14: =IF(R$83=0,"n.a.",R14/R$83) -> 0.030649766 | T14: 9823612.9 | U14: =IF(T$83=0,"n.a.",T14/T$83) -> 0.027100486 | V14: 10737250 | W14: =IF(V$83=0,"n.a.",V14/V$83) -> 0.02861506 | X14: 11365924 | Y14: =IF(X$83=0,"n.a.",X14/X$83) -> 0.030839984 | Z14: 15163083 | AA14: =IF(Z$83=0,"n.a.",Z14/Z$83) -> 0.034918015 | AB14: =SUM(D14,F14,H14,J14,L14,N14,P14,R14,T14,V14,X14,Z14) -> 1.2753975e+08 | AC14: =IF($AB$83=0,"n.a.",AB14/$AB$83) -> 0.029348827
B15: =COUNTIFS($AB$7:$AB$75,">"&AB15)+1 -> 9 | C15: Branch 9 | D15: 10931530 | E15: =IF(D$83=0,"n.a.",D15/D$83) -> 0.031341055 | F15: 9338428.7 | G15: =IF(F$83=0,"n.a.",F15/F$83) -> 0.028387131 | H15: 8746298.7 | I15: =IF(H$83=0,"n.a.",H15/H$83) -> 0.025936206 | J15: 10522433 | K15: =IF(J$83=0,"n.a.",J15/J$83) -> 0.03075894 | L15: 9971056.3 | M15: =IF(L$83=0,"n.a.",L15/L$83) -> 0.028480489 | N15: 9691320.3 | O15: =IF(N$83=0,"n.a.",N15/N$83) -> 0.027854569 | P15: 11216681 | Q15: =IF(P$83=0,"n.a.",P15/P$83) -> 0.030280568 | R15: 12048699 | S15: =IF(R$83=0,"n.a.",R15/R$83) -> 0.031739709 | T15: 10566330 | U15: =IF(T$83=0,"n.a.",T15/T$83) -> 0.029149426 | V15: 10172732 | W15: =IF(V$83=0,"n.a.",V15/V$83) -> 0.027110604 | X15: 10346160 | Y15: =IF(X$83=0,"n.a.",X15/X$83) -> 0.028072983 | Z15: 11832218 | AA15: =IF(Z$83=0,"n.a.",Z15/Z$83) -> 0.027247597 | AB15: =SUM(D15,F15,H15,J15,L15,N15,P15,R15,T15,V15,X15,Z15) -> 1.2538389e+08 | AC15: =IF($AB$83=0,"n.a.",AB15/$AB$83) -> 0.02885273
B16: =COUNTIFS($AB$7:$AB$75,">"&AB16)+1 -> 10 | C16: Branch 10 | D16: 11735149 | E16: =IF(D$83=0,"n.a.",D16/D$83) -> 0.033645057 | F16: 10501309 | G16: =IF(F$83=0,"n.a.",F16/F$83) -> 0.031922075 | H16: 11017044 | I16: =IF(H$83=0,"n.a.",H16/H$83) -> 0.032669856 | J16: 10096941 | K16: =IF(J$83=0,"n.a.",J16/J$83) -> 0.029515151 | L16: 10602863 | M16: =IF(L$83=0,"n.a.",L16/L$83) -> 0.030285129 | N16: 10493261 | O16: =IF(N$83=0,"n.a.",N16/N$83) -> 0.030159487 | P16: 10261426 | Q16: =IF(P$83=0,"n.a.",P16/P$83) -> 0.02770176 | R16: 9717069.6 | S16: =IF(R$83=0,"n.a.",R16/R$83) -> 0.025597531 | T16: 9867408.2 | U16: =IF(T$83=0,"n.a.",T16/T$83) -> 0.027221304 | V16: 10470269 | W16: =IF(V$83=0,"n.a.",V16/V$83) -> 0.027903549 | X16: 10047915 | Y16: =IF(X$83=0,"n.a.",X16/X$83) -> 0.027263734 | Z16: 10352008 | AA16: =IF(Z$83=0,"n.a.",Z16/Z$83) -> 0.023838924 | AB16: =SUM(D16,F16,H16,J16,L16,N16,P16,R16,T16,V16,X16,Z16) -> 1.2516266e+08 | AC16: =IF($AB$83=0,"n.a.",AB16/$AB$83) -> 0.028801823
B17: =COUNTIFS($AB$7:$AB$75,">"&AB17)+1 -> 11 | C17: Branch 11 | D17: 9722190.8 | E17: =IF(D$83=0,"n.a.",D17/D$83) -> 0.02787384 | F17: 9399090.2 | G17: =IF(F$83=0,"n.a.",F17/F$83) -> 0.028571531 | H17: 10692453 | I17: =IF(H$83=0,"n.a.",H17/H$83) -> 0.031707315 | J17: 10007121 | K17: =IF(J$83=0,"n.a.",J17/J$83) -> 0.02925259 | L17: 10310329 | M17: =IF(L$83=0,"n.a.",L17/L$83) -> 0.029449559 | N17: 9921227.5 | O17: =IF(N$83=0,"n.a.",N17/N$83) -> 0.028515363 | P17: 10473007 | Q17: =IF(P$83=0,"n.a.",P17/P$83) -> 0.028272945 | R17: 10253538 | S17: =IF(R$83=0,"n.a.",R17/R$83) -> 0.027010741 | T17: 10169571 | U17: =IF(T$83=0,"n.a.",T17/T$83) -> 0.028054882 | V17: 10427164 | W17: =IF(V$83=0,"n.a.",V17/V$83) -> 0.027788672 | X17: 10475768 | Y17: =IF(X$83=0,"n.a.",X17/X$83) -> 0.028424659 | Z17: 11863735 | AA17: =IF(Z$83=0,"n.a.",Z17/Z$83) -> 0.027320176 | AB17: =SUM(D17,F17,H17,J17,L17,N17,P17,R17,T17,V17,X17,Z17) -> 1.2371519e+08 | AC17: =IF($AB$83=0,"n.a.",AB17/$AB$83) -> 0.028468738
B18: =COUNTIFS($AB$7:$AB$75,">"&AB18)+1 -> 12 | C18: Branch 12 | D18: 9209808.6 | E18: =IF(D$83=0,"n.a.",D18/D$83) -> 0.026404824 | F18: 8592004.8 | G18: =IF(F$83=0,"n.a.",F18/F$83) -> 0.026118137 | H18: 7833659.8 | I18: =IF(H$83=0,"n.a.",H18/H$83) -> 0.023229873 | J18: 9120905.3 | K18: =IF(J$83=0,"n.a.",J18/J$83) -> 0.026662025 | L18: 8291412.1 | M18: =IF(L$83=0,"n.a.",L18/L$83) -> 0.023682894 | N18: 10139099 | O18: =IF(N$83=0,"n.a.",N18/N$83) -> 0.029141563 | P18: 12323581 | Q18: =IF(P$83=0,"n.a.",P18/P$83) -> 0.033268756 | R18: 14307742 | S18: =IF(R$83=0,"n.a.",R18/R$83) -> 0.03769067 | T18: 9473309.2 | U18: =IF(T$83=0,"n.a.",T18/T$83) -> 0.0261341 | V18: 9875851.5 | W18: =IF(V$83=0,"n.a.",V18/V$83) -> 0.02631941 | X18: 8423071.8 | Y18: =IF(X$83=0,"n.a.",X18/X$83) -> 0.022854929 | Z18: 13236028 | AA18: =IF(Z$83=0,"n.a.",Z18/Z$83) -> 0.030480335 | AB18: =SUM(D18,F18,H18,J18,L18,N18,P18,R18,T18,V18,X18,Z18) -> 1.2082647e+08 | AC18: =IF($AB$83=0,"n.a.",AB18/$AB$83) -> 0.027804
... B43: =COUNTIFS($AB$7:$AB$75,">"&AB43)+1 -> 37 | C43: Branch 37 | D43: 4428546.6 | E43: =IF(D$83=0,"n.a.",D43/D$83) -> 0.012696788 | F43: 4314116.2 | G43: =IF(F$83=0,"n.a.",F43/F$83) -> 0.013114131 | H43: 4763964.5 | I43: =IF(H$83=0,"n.a.",H43/H$83) -> 0.014127023 | J43: 4918564.1 | K43: =IF(J$83=0,"n.a.",J43/J$83) -> 0.014377836 | L43: 4878333.8 | M43: =IF(L$83=0,"n.a.",L43/L$83) -> 0.013934064 | N43: 4685160.3 | O43: =IF(N$83=0,"n.a.",N43/N$83) -> 0.013465979 | P43: 5053123.1 | Q43: =IF(P$83=0,"n.a.",P43/P$83) -> 0.013641418 | R43: 4899978.6 | S43: =IF(R$83=0,"n.a.",R43/R$83) -> 0.01290794 | T43: 4634335.9 | U43: =IF(T$83=0,"n.a.",T43/T$83) -> 0.012784782 | V43: 5136794.4 | W43: =IF(V$83=0,"n.a.",V43/V$83) -> 0.013689695 | X43: 4905026.9 | Y43: =IF(X$83=0,"n.a.",X43/X$83) -> 0.013309164 | Z43: 5409359.6 | AA43: =IF(Z$83=0,"n.a.",Z43/Z$83) -> 0.01245684 | AB43: =SUM(D43,F43,H43,J43,L43,N43,P43,R43,T43,V43,X43,Z43) -> 58027304 | AC43: =IF($AB$83=0,"n.a.",AB43/$AB$83) -> 0.013352961
B44: =COUNTIFS($AB$7:$AB$75,">"&AB44)+1 -> 38 | C44: Branch 38 | L44: 206903.25 | M44: =IF(L$83=0,"n.a.",L44/L$83) -> 0.00059098109 | N44: 6393006 | O44: =IF(N$83=0,"n.a.",N44/N$83) -> 0.01837463 | P44: 6510135.2 | Q44: =IF(P$83=0,"n.a.",P44/P$83) -> 0.01757477 | R44: 6952322 | S44: =IF(R$83=0,"n.a.",R44/R$83) -> 0.018314398 | T44: 5441548.1 | U44: =IF(T$83=0,"n.a.",T44/T$83) -> 0.015011646 | V44: 5719362.7 | W44: =IF(V$83=0,"n.a.",V44/V$83) -> 0.015242256 | X44: 5152440.4 | Y44: =IF(X$83=0,"n.a.",X44/X$83) -> 0.013980489 | Z44: 7788723 | AA44: =IF(Z$83=0,"n.a.",Z44/Z$83) -> 0.017936112 | AB44: =SUM(D44,F44,H44,J44,L44,N44,P44,R44,T44,V44,X44,Z44) -> 44164441 | AC44: =IF($AB$83=0,"n.a.",AB44/$AB$83) -> 0.010162906
B45: =COUNTIFS($AB$7:$AB$75,">"&AB45)+1 -> 39 | C45: Branch 39 | D45: 3503121.2 | E45: =IF(D$83=0,"n.a.",D45/D$83) -> 0.010043563 | F45: 3208512.3 | G45: =IF(F$83=0,"n.a.",F45/F$83) -> 0.0097532959 | H45: 2468122 | I45: =IF(H$83=0,"n.a.",H45/H$83) -> 0.0073189496 | J45: 3408735.1 | K45: =IF(J$83=0,"n.a.",J45/J$83) -> 0.0099643374 | L45: 3493966.9 | M45: =IF(L$83=0,"n.a.",L45/L$83) -> 0.0099798741 | N45: 3344959.6 | O45: =IF(N$83=0,"n.a.",N45/N$83) -> 0.0096140056 | P45: 3694791.5 | Q45: =IF(P$83=0,"n.a.",P45/P$83) -> 0.0099744641 | R45: 3478128.7 | S45: =IF(R$83=0,"n.a.",R45/R$83) -> 0.0091623825 | T45: 3507838.5 | U45: =IF(T$83=0,"n.a.",T45/T$83) -> 0.0096771043 | V45: 3398428.2 | W45: =IF(V$83=0,"n.a.",V45/V$83) -> 0.0090569026 | X45: 3408157.7 | Y45: =IF(X$83=0,"n.a.",X45/X$83) -> 0.0092476006 | Z45: 3526654.3 | AA45: =IF(Z$83=0,"n.a.",Z45/Z$83) -> 0.0081212884 | AB45: =SUM(D45,F45,H45,J45,L45,N45,P45,R45,T45,V45,X45,Z45) -> 40441416 | AC45: =IF($AB$83=0,"n.a.",AB45/$AB$83) -> 0.0093061818
B46: =COUNTIFS($AB$7:$AB$75,">"&AB46)+1 -> 40 | C46: Branch 40 | D46: 2199674.1 | E46: =IF(D$83=0,"n.a.",D46/D$83) -> 0.0063065378 | F46: 2212948.5 | G46: =IF(F$83=0,"n.a.",F46/F$83) -> 0.0067269624 | H46: 3010367.6 | I46: =IF(H$83=0,"n.a.",H46/H$83) -> 0.0089269205 | J46: 2610442.8 | K46: =IF(J$83=0,"n.a.",J46/J$83) -> 0.0076307874 | L46: 2664638.8 | M46: =IF(L$83=0,"n.a.",L46/L$83) -> 0.0076110508 | N46: 2730251.8 | O46: =IF(N$83=0,"n.a.",N46/N$83) -> 0.0078472266 | P46: 2972476.8 | Q46: =IF(P$83=0,"n.a.",P46/P$83) -> 0.0080245026 | R46: 3047007.5 | S46: =IF(R$83=0,"n.a.",R46/R$83) -> 0.0080266863 | T46: 2566715.7 | U46: =IF(T$83=0,"n.a.",T46/T$83) -> 0.0070808209 | V46: 3293803.9 | W46: =IF(V$83=0,"n.a.",V46/V$83) -> 0.0087780761 | X46: 3189387.9 | Y46: =IF(X$83=0,"n.a.",X46/X$83) -> 0.0086539966 | Z46: 4110650.5 | AA46: =IF(Z$83=0,"n.a.",Z46/Z$83) -> 0.0094661329 | AB46: =SUM(D46,F46,H46,J46,L46,N46,P46,R46,T46,V46,X46,Z46) -> 34608366 | AC46: =IF($AB$83=0,"n.a.",AB46/$AB$83) -> 0.0079639087
B47: =COUNTIFS($AB$7:$AB$75,">"&AB47)+1 -> 41 | C47: Branch 41 | D47: 2666370.4 | E47: =IF(D$83=0,"n.a.",D47/D$83) -> 0.0076445713 | F47: 2819709.9 | G47: =IF(F$83=0,"n.a.",F47/F$83) -> 0.0085714071 | H47: 2262430.5 | I47: =IF(H$83=0,"n.a.",H47/H$83) -> 0.0067089938 | J47: 2963351.3 | K47: =IF(J$83=0,"n.a.",J47/J$83) -> 0.0086624017 | L47: 3181179.3 | M47: =IF(L$83=0,"n.a.",L47/L$83) -> 0.0090864538 | N47: 2405860.3 | O47: =IF(N$83=0,"n.a.",N47/N$83) -> 0.0069148682 | P47: 3228359.2 | Q47: =IF(P$83=0,"n.a.",P47/P$83) -> 0.0087152829 | R47: 2993711 | S47: =IF(R$83=0,"n.a.",R47/R$83) -> 0.0078862883 | T47: 2948335.2 | U47: =IF(T$83=0,"n.a.",T47/T$83) -> 0.0081335979 | V47: 2881550 | W47: =IF(V$83=0,"n.a.",V47/V$83) -> 0.0076794083 | X47: 2765464.4 | Y47: =IF(X$83=0,"n.a.",X47/X$83) -> 0.0075037343 | Z47: 2881452.8 | AA47: =IF(Z$83=0,"n.a.",Z47/Z$83) -> 0.0066354986 | AB47: =SUM(D47,F47,H47,J47,L47,N47,P47,R47,T47,V47,X47,Z47) -> 33997774 | AC47: =IF($AB$83=0,"n.a.",AB47/$AB$83) -> 0.0078234024
